#VRML_SIM R2021b utf8
WorldInfo {
  coordinateSystem "NUE"
}
Viewpoint {
  orientation -0.662626391358055 0.7323438598553184 0.15683984317773061 0.5837014279964436
  position 0.5776381959352379 0.8288130188771003 1.3760097037494157
}
TexturedBackground {
}
TexturedBackgroundLight {
}
Robot {
  translation 0.15791894665219355 0.006097118965823725 -0.36799145335303945
  rotation 8.188953274181072e-06 0.9999999957124595 9.223893784781919e-05 2.0318451225500143
  children [
    GPS {
    }
    DEF WL Hinge2Joint {
      jointParameters HingeJointParameters {
        position -0.07987318006548905
        axis 0 1 0
        anchor 0.045 0.025 -0.0505
      }
      jointParameters2 JointParameters {
        position -14.677725298104123
      }
      device [
        Brake {
          name "steer_left_brake"
        }
        RotationalMotor {
          name "steer_left_motor"
        }
      ]
      device2 [
        RotationalMotor {
          name "front_left_motor"
        }
      ]
      endPoint Solid {
        translation 0.045 0.025 -0.0505
        rotation 0.39381550470748444 -0.6644985826170257 -0.6350991906402915 2.482738169547788
        children [
          DEF WL Shape {
            appearance PBRAppearance {
              baseColor 0 0 0
              roughness 1
              metalness 0
            }
            geometry Cylinder {
              height 0.01
              radius 0.025
            }
          }
        ]
        name "solid(3)"
        boundingObject USE WL
        physics Physics {
        }
      }
    }
    InertialUnit {
      name "imu"
    }
    DEF WR Hinge2Joint {
      jointParameters HingeJointParameters {
        position 0.1086255581162594
        axis 0 1 0
        anchor 0.045 0.025 0.0505
      }
      jointParameters2 JointParameters {
        position -24.547516134769523
      }
      device [
        Brake {
          name "steer_right_brake"
        }
        RotationalMotor {
          name "steer_right_motor"
        }
      ]
      device2 [
        RotationalMotor {
          name "front_right_motor"
        }
      ]
      endPoint Solid {
        translation 0.045 0.025 0.0505
        rotation 0.920015657644281 0.32190938622237225 0.22348498104189612 1.686664160692993
        children [
          DEF Wheel_Right Shape {
            appearance PBRAppearance {
              baseColor 0 0 0
              roughness 1
              metalness 0
            }
            geometry Cylinder {
              height 0.01
              radius 0.025
            }
          }
        ]
        name "solid(2)"
        boundingObject USE Wheel_Right
        physics Physics {
        }
      }
    }
    DEF Windscreen Solid {
      translation 0.066 0.051 0
      children [
        Shape {
          appearance PBRAppearance {
            baseColor 0.08 0.78 1
            roughness 0.2
            metalness 0.8
          }
          geometry Box {
            size 0.03 0.01 0.08
          }
        }
      ]
      name "solid(4)"
    }
    DEF DWL HingeJoint {
      jointParameters HingeJointParameters {
        position -11.35958605105531
        axis 0 0 1
        anchor -0.045 0.025 -0.0505
      }
      device [
        Brake {
          name "left_brake"
        }
        PositionSensor {
          name "left_pos_sensor"
        }
        RotationalMotor {
          name "left_motor"
        }
      ]
      endPoint Solid {
        translation -0.045 0.025 -0.0505
        rotation -0.7161529796349076 -0.49352137697862086 0.4935195641767098 1.898626477566454
        children [
          DEF Driven_Wheel_Left Shape {
            appearance PBRAppearance {
              baseColor 0 0 0
              roughness 1
              metalness 0
            }
            geometry Cylinder {
              height 0.01
              radius 0.025
            }
          }
        ]
        name "solid(1)"
        boundingObject USE Driven_Wheel_Left
        physics Physics {
        }
      }
    }
    DEF DWR HingeJoint {
      jointParameters HingeJointParameters {
        position -22.718096765532643
        axis 0 0 1
        anchor -0.045 0.025 0.0505
      }
      device [
        Brake {
          name "right_brake"
        }
        PositionSensor {
          name "right_pos_sensor"
        }
        RotationalMotor {
          name "right_motor"
        }
      ]
      endPoint Solid {
        translation -0.045 0.025 0.05049999999999999
        rotation -0.2597348705277622 -0.6828401066261858 0.6828375984190279 2.6333550392334777
        children [
          DEF Driven_Wheel_Right Shape {
            appearance PBRAppearance {
              baseColor 0 0 0
              roughness 1
              metalness 0
            }
            geometry Cylinder {
              height 0.01
              radius 0.025
            }
          }
        ]
        boundingObject USE Driven_Wheel_Right
        physics Physics {
        }
      }
    }
    DEF Chassis Transform {
      translation 0 0.035 0
      children [
        Shape {
          appearance PBRAppearance {
            baseColor 1 0.78 0.08
            roughness 1
            metalness 0.25
          }
          geometry Box {
            size 0.16 0.04 0.1
          }
        }
      ]
    }
    Accelerometer {
    }
  ]
  boundingObject USE Chassis
  physics Physics {
  }
  controller "kf_controller_2"
}
UnevenTerrain {
  size 50 0.01 50
}
